<robot
  name="explorer_arm">
  <link
    name="base_link">
    <inertial>
      <origin
        xyz="5.30295138154639E-18 4.68666482685722E-18 -0.00537654262053586"
        rpy="0 0 0" />
      <mass
        value="0.123004220906763" />
      <inertia
        ixx="0.000126778477793128"
        ixy="1.16890546721093E-19"
        ixz="4.48838794212588E-21"
        iyy="0.000202905328983021"
        iyz="-1.00750827946994E-21"
        izz="0.000328057202392826" />
    </inertial>
    <visual>
      <origin
        xyz="0 0 0"
        rpy="0 0 0" />
      <geometry>
        <mesh
          filename="package://explorer_arm/meshes/base_link.STL" />
      </geometry>
      <material
        name="">
        <color
          rgba="0.898039215686275 0.917647058823529 0.929411764705882 1" />
      </material>
    </visual>
    <collision>
      <origin
        xyz="0 0 0"
        rpy="0 0 0" />
      <geometry>
        <mesh
          filename="package://explorer_arm/meshes/base_link.STL" />
      </geometry>
    </collision>
  </link>
  <link
    name="link1">
    <inertial>
      <origin
        xyz="-1.57296051184197E-15 -0.0164490622106135 0.0388817981392033"
        rpy="0 0 0" />
      <mass
        value="0.951158934947069" />
      <inertia
        ixx="0.00265081329327507"
        ixy="-1.0638733817514E-17"
        ixz="2.10470746733749E-17"
        iyy="0.00136964363562847"
        iyz="0.000498056019035245"
        izz="0.00197220269876933" />
    </inertial>
    <visual>
      <origin
        xyz="0 0 0"
        rpy="0 0 0" />
      <geometry>
        <mesh
          filename="package://explorer_arm/meshes/link1.STL" />
      </geometry>
      <material
        name="">
        <color
          rgba="1 1 1 1" />
      </material>
    </visual>
    <collision>
      <origin
        xyz="0 0 0"
        rpy="0 0 0" />
      <geometry>
        <mesh
          filename="package://explorer_arm/meshes/link1.STL" />
      </geometry>
    </collision>
  </link>
  <joint
    name="joint1"
    type="revolute">
    <origin
      xyz="0 0 0"
      rpy="0 0 0" />
    <parent
      link="base_link" />
    <child
      link="link1" />
    <axis
      xyz="0 0 1" />
    <limit
      lower="-1.39626"
      upper="1.39626"
      effort="0"
      velocity="0" />
  </joint>
  <link
    name="link2">
    <inertial>
      <origin
        xyz="0.218960913861498 -0.0141708664792835 0.0336877699607546"
        rpy="0 0 0" />
      <mass
        value="0.471157366596544" />
      <inertia
        ixx="0.000550706117649387"
        ixy="0.00079764310293283"
        ixz="-0.00128994903099265"
        iyy="0.00879208773534429"
        iyz="0.00012173568220917"
        izz="0.00880708498261866" />
    </inertial>
    <visual>
      <origin
        xyz="0 0 0"
        rpy="0 0 0" />
      <geometry>
        <mesh
          filename="package://explorer_arm/meshes/link2.STL" />
      </geometry>
      <material
        name="">
        <color
          rgba="0.650980392156863 0.619607843137255 0.588235294117647 1" />
      </material>
    </visual>
    <collision>
      <origin
        xyz="0 0 0"
        rpy="0 0 0" />
      <geometry>
        <mesh
          filename="package://explorer_arm/meshes/link2.STL" />
      </geometry>
    </collision>
  </link>
  <joint
    name="joint2"
    type="revolute">
    <origin
      xyz="0 -0.013 0.094735"
      rpy="2.7749E-16 -1.3269E-16 -1.9429E-16" />
    <parent
      link="link1" />
    <child
      link="link2" />
    <axis
      xyz="0 -1 0" />
    <limit
      lower="0.5233333333"
      upper="2.529444444"
      effort="0"
      velocity="0" />
  </joint>
  <link
    name="link3">
    <inertial>
      <origin
        xyz="-0.188265294609535 0.00719049764048552 0.0131455777449244"
        rpy="0 0 0" />
      <mass
        value="0.340508547249228" />
      <inertia
        ixx="0.000111611599254139"
        ixy="0.000207740791119363"
        ixz="0.000556461901337218"
        iyy="0.00740941885776415"
        iyz="-1.35938363387933E-05"
        izz="0.0073578696443495" />
    </inertial>
    <visual>
      <origin
        xyz="0 0 0"
        rpy="0 0 0" />
      <geometry>
        <mesh
          filename="package://explorer_arm/meshes/link3.STL" />
      </geometry>
      <material
        name="">
        <color
          rgba="0.650980392156863 0.619607843137255 0.588235294117647 1" />
      </material>
    </visual>
    <collision>
      <origin
        xyz="0 0 0"
        rpy="0 0 0" />
      <geometry>
        <mesh
          filename="package://explorer_arm/meshes/link3.STL" />
      </geometry>
    </collision>
  </link>
  <joint
    name="joint3"
    type="revolute">
    <origin
      xyz="0.34672 0.024 0.053185"
      rpy="1.2214E-15 0.1 -3.7062E-15" />
    <parent
      link="link2" />
    <child
      link="link3" />
    <axis
      xyz="0 -1 0" />
    <limit
      lower="0.3488888"
      upper="2.5294444"
      effort="0"
      velocity="0" />
  </joint>
  <link
    name="link4">
    <inertial>
      <origin
        xyz="0.0127610247457266 -1.08832644979406E-09 1.11490469634212E-09"
        rpy="0 0 0" />
      <mass
        value="0.0168856923737981" />
      <inertia
        ixx="1.00151971364091E-05"
        ixy="-1.10643678735093E-20"
        ixz="-6.35274710440725E-22"
        iyy="3.94077438699999E-06"
        iyz="-1.46829911554915E-07"
        izz="1.21420239431158E-05" />
    </inertial>
    <visual>
      <origin
        xyz="0 0 0"
        rpy="0 0 0" />
      <geometry>
        <mesh
          filename="package://explorer_arm/meshes/link4.STL" />
      </geometry>
      <material
        name="">
        <color
          rgba="0.898039215686275 0.917647058823529 0.929411764705882 1" />
      </material>
    </visual>
    <collision>
      <origin
        xyz="0 0 0"
        rpy="0 0 0" />
      <geometry>
        <mesh
          filename="package://explorer_arm/meshes/link4.STL" />
      </geometry>
    </collision>
  </link>
  <joint
    name="joint4"
    type="revolute">
    <origin
      xyz="-0.37504 0.006 0.019228"
      rpy="-3.1416 -0.052784 -3.1416" />
    <parent
      link="link3" />
    <child
      link="link4" />
    <axis
      xyz="1 0 0" />
    <limit
      lower="-1.57"
      upper="1.57"
      effort="0"
      velocity="0" />
  </joint>
  <link
    name="link5">
    <inertial>
      <origin
        xyz="-0.0277631808703815 -0.00993024655588244 0.0158727705342218"
        rpy="0 0 0" />
      <mass
        value="0.176496925110268" />
      <inertia
        ixx="8.71848264444776E-05"
        ixy="-5.24503988945605E-07"
        ixz="5.76084946082367E-06"
        iyy="7.75931086752916E-05"
        iyz="-9.19170266270102E-07"
        izz="4.46773841632012E-05" />
    </inertial>
    <visual>
      <origin
        xyz="0 0 0"
        rpy="0 0 0" />
      <geometry>
        <mesh
          filename="package://explorer_arm/meshes/link5.STL" />
      </geometry>
      <material
        name="">
        <color
          rgba="0.847058823529412 0.847058823529412 0.847058823529412 1" />
      </material>
    </visual>
    <collision>
      <origin
        xyz="0 0 0"
        rpy="0 0 0" />
      <geometry>
        <mesh
          filename="package://explorer_arm/meshes/link5.STL" />
      </geometry>
    </collision>
  </link>
  <joint
    name="joint5"
    type="revolute">
    <origin
      xyz="0.032 -0.025996 -0.00046526"
      rpy="-1.8528 0.017896 -1.5708" />
    <parent
      link="link4" />
    <child
      link="link5" />
    <axis
      xyz="1 0 0" />
    <limit
      lower="-0.69777777"
      upper="1.39"
      effort="0"
      velocity="0" />
  </joint>
  <link
    name="link6">
    <inertial>
      <origin
        xyz="0.0245880351097211 -0.00326907351610177 -5.42849800771184E-05"
        rpy="0 0 0" />
      <mass
        value="0.106174750561717" />
      <inertia
        ixx="4.29253431142189E-05"
        ixy="-9.01215408103069E-08"
        ixz="-1.08939932358241E-06"
        iyy="3.46445626823301E-05"
        iyz="3.64117468216087E-07"
        izz="3.9799908549543E-05" />
    </inertial>
    <visual>
      <origin
        xyz="0 0 0"
        rpy="0 0 0" />
      <geometry>
        <mesh
          filename="package://explorer_arm/meshes/link6.STL" />
      </geometry>
      <material
        name="">
        <color
          rgba="1 1 1 1" />
      </material>
    </visual>
    <collision>
      <origin
        xyz="0 0 0"
        rpy="0 0 0" />
      <geometry>
        <mesh
          filename="package://explorer_arm/meshes/link6.STL" />
      </geometry>
    </collision>
  </link>
  <joint
    name="joint6"
    type="revolute">
    <origin
      xyz="-0.0298 0.00025 0.0578"
      rpy="3.1416 -1.5708 0" />
    <parent
      link="link5" />
    <child
      link="link6" />
    <axis
      xyz="1 0 0" />
    <limit
      lower="-1.57"
      upper="1.57"
      effort="0"
      velocity="0" />
  </joint>
</robot>
