<?xml version="1.0" encoding="utf-8" ?>
<robot name="rescue_urdf">
	<material name="Black">
		<color rgba="0.2 0.2 0.2 1.0" />
	</material>
	<material name="TransparentBlack">
		<color rgba="0.2 0.2 0.2 0.8" />
	</material>
	<material name="Orange">
		<color rgba="1.0  0.55 0.0 1.0" />
	</material>
	<material name="Grey">
		<color rgba="0.7 0.7 0.7 1.0" />
	</material>
	<material name="DarkGrey">
		<color rgba="0.3 0.3 0.3 1.0" />
	</material>
	<material name="Red">
		<color rgba="0.8 0.0 0.0 1.0" />
	</material>
	<material name="White">
		<color rgba="1.0 1.0 1.0 1.0" />
	</material>
	<material name="OffWhite">
		<color rgba="0.8 0.8 0.8 1.0" />
	</material>
	<material name="Blue">
		<color rgba="0.0 0.0 0.8 1.0" />
	</material>
	<material name="Green">
		<color rgba="0.0 0.8 0.0 1.0" />
	</material>
	<material name="TransparentGreen">
		<color rgba="0.0 0.8 0.0 0.5" />
	</material>
	<link name="base_link">
		<inertial>
			<origin xyz="2.019E-18 -4.2223E-19 -0.0015117" rpy="0 0 0" />
			<mass value="0.062832" />
			<inertia ixx="5.4116E-05" ixy="-8.7997E-21" ixz="2.9353E-22" iyy="8.0393E-06" iyz="3.5981E-22" izz="5.8643E-05" />
		</inertial>
		<visual>
			<origin xyz="0 0 0" rpy="0 0 0" />
			<geometry>
				<mesh filename="package://rescue_new/meshes/base_link.STL" />
			</geometry>
			<material name="">
				<color rgba="0.2 0.2 0.2 1" />
			</material>
		</visual>
		<collision>
			<origin xyz="0 0 0" rpy="0 0 0" />
			<geometry>
				<mesh filename="package://rescue_new/meshes/base_link.STL" />
			</geometry>
		</collision>
	</link>
	<link name="front_back_base">
		<inertial>
			<origin xyz="5.755E-18 -0.00029577 0.0015169" rpy="0 0 0" />
			<mass value="0.062832" />
			<inertia ixx="8.0393E-06" ixy="4.75E-21" ixz="-3.5459E-22" iyy="5.4121E-05" iyz="-1.5765E-07" izz="5.8638E-05" />
		</inertial>
		<visual>
			<origin xyz="0 0 0" rpy="0 0 0" />
			<geometry>
				<mesh filename="package://rescue_new/meshes/front_back_base.STL" />
			</geometry>
			<material name="">
				<color rgba="0.2 0.2 0.2 1" />
			</material>
		</visual>
		<collision>
			<origin xyz="0 0 0" rpy="0 0 0" />
			<geometry>
				<mesh filename="package://rescue_new/meshes/front_back_base.STL" />
			</geometry>
		</collision>
	</link>
	<joint name="joint_front_back" type="revolute">
		<origin xyz="0 0 -0.01" rpy="0 0 0" />
		<parent link="base_link" />
		<child link="front_back_base" />
		<axis xyz="0 1 0" />
		<limit lower="-1.05" upper="1.05" effort="0" velocity="0" />
	</joint>
	<link name="frame_Link">
		<inertial>
			<origin xyz="0.00077984 8.3381E-05 -0.0066376" rpy="0 0 0" />
			<mass value="36.094" />
			<inertia ixx="0.57342" ixy="0.00047616" ixz="0.0059852" iyy="1.0475" iyz="0.00063993" izz="1.4159" />
		</inertial>
		<visual>
			<origin xyz="0 0 0" rpy="0 0 0" />
			<geometry>
				<mesh filename="package://rescue_new/meshes/frame_Link.STL" />
			</geometry>
			<material name="">
				<color rgba="0.1 0.1 0.1 1" />
			</material>
		</visual>
		<collision>
			<origin xyz="0 0 0" rpy="0 0 0" />
			<geometry>
				<mesh filename="package://rescue_new/meshes/frame_Link.STL" />
			</geometry>
		</collision>
	</link>
	<joint name="robot_left_right" type="revolute">
		<origin xyz="0 0 0.105" rpy="0 0 0" />
		<parent link="front_back_base" />
		<child link="frame_Link" />
		<axis xyz="1 0 0" />
		<limit lower="-1.05" upper="1.05" effort="0" velocity="0" />
	</joint>
	<!-- 副履带部分 -->
	<link name="left_up_fin_Link">
		<inertial>
			<origin xyz="0.088814 -0.028 -0.0028953" rpy="0 0 0" />
			<mass value="3.2159" />
			<inertia ixx="0.0074694" ixy="6.0445E-18" ixz="-0.00091416" iyy="0.04127" iyz="-3.7665E-19" izz="0.035481" />
		</inertial>
		<visual>
			<origin xyz="0 0 0" rpy="0 0 0" />
			<geometry>
				<mesh filename="package://rescue_new/meshes/left_up_fin_Link.STL" />
			</geometry>
			<material name="">
				<color rgba="0.2 0.2 0.2 1" />
			</material>
		</visual>
		<collision>
			<origin xyz="0 0 0" rpy="0 0 0" />
			<geometry>
				<mesh filename="package://rescue_new/meshes/left_up_fin_Link.STL" />
			</geometry>
		</collision>
	</link>
	<joint name="left_up_fin_base_joint" type="revolute">
		<origin xyz="0.2 0.2485 0" rpy="0 0 0" />
		<parent link="frame_Link" />
		<child link="left_up_fin_Link" />
		<axis xyz="0 -1 0" />
		<limit lower="-1.57" upper="1.57" effort="0" velocity="0" />
	</joint>
	<link name="right_up_fin_Link">
		<inertial>
			<origin xyz="0.088814 0.028 -0.0028953" rpy="0 0 0" />
			<mass value="3.2159" />
			<inertia ixx="0.0074694" ixy="7.0741E-18" ixz="-0.00091416" iyy="0.04127" iyz="-4.3716E-20" izz="0.035481" />
		</inertial>
		<visual>
			<origin xyz="0 0 0" rpy="0 0 0" />
			<geometry>
				<mesh filename="package://rescue_new/meshes/right_up_fin_Link.STL" />
			</geometry>
			<material name="">
				<color rgba="0.2 0.2 0.2 1" />
			</material>
		</visual>
		<collision>
			<origin xyz="0 0 0" rpy="0 0 0" />
			<geometry>
				<mesh filename="package://rescue_new/meshes/right_up_fin_Link.STL" />
			</geometry>
		</collision>
	</link>
	<joint name="right_up_fin_base_joint" type="revolute">
		<origin xyz="0.2 -0.2485 0" rpy="0 0 0" />
		<parent link="frame_Link" />
		<child link="right_up_fin_Link" />
		<axis xyz="0 -1 0" />
		<limit lower="-1.57" upper="1.57" effort="0" velocity="0" />
	</joint>
	<link name="left_down_fin_Link">
		<inertial>
			<origin xyz="-0.088854 -0.028 0.0011636" rpy="0 0 0" />
			<mass value="3.2159" />
			<inertia ixx="0.0074444" ixy="6.2159E-18" ixz="-0.00036755" iyy="0.04127" iyz="-8.4555E-21" izz="0.035506" />
		</inertial>
		<visual>
			<origin xyz="0 0 0" rpy="0 0 0" />
			<geometry>
				<mesh filename="package://rescue_new/meshes/left_down_fin_Link.STL" />
			</geometry>
			<material name="">
				<color rgba="0.2 0.2 0.2 1" />
			</material>
		</visual>
		<collision>
			<origin xyz="0 0 0" rpy="0 0 0" />
			<geometry>
				<mesh filename="package://rescue_new/meshes/left_down_fin_Link.STL" />
			</geometry>
		</collision>
	</link>
	<joint name="left_down_fin_base_joint" type="revolute">
		<origin xyz="-0.2 0.2485 0" rpy="0 0 0" />
		<parent link="frame_Link" />
		<child link="left_down_fin_Link" />
		<axis xyz="0 -1 0" />
		<limit lower="-1.57" upper="1.57" effort="0" velocity="0" />
	</joint>
	<link name="right_down_fin_Link">
		<inertial>
			<origin xyz="-0.088854 -0.469 0.0011636" rpy="0 0 0" />
			<mass value="3.2159" />
			<inertia ixx="0.0074444" ixy="5.5311E-18" ixz="-0.00036755" iyy="0.04127" iyz="2.278E-19" izz="0.035506" />
		</inertial>
		<visual>
			<origin xyz="0 0 0" rpy="0 0 0" />
			<geometry>
				<mesh filename="package://rescue_new/meshes/right_down_fin_Link.STL" />
			</geometry>
			<material name="">
				<color rgba="0.2 0.2 0.2 1" />
			</material>
		</visual>
		<collision>
			<origin xyz="0 0 0" rpy="0 0 0" />
			<geometry>
				<mesh filename="package://rescue_new/meshes/right_down_fin_Link.STL" />
			</geometry>
		</collision>
	</link>
	<joint name="right_down_fin_base_joint" type="revolute">
		<origin xyz="-0.2 0.2485 0" rpy="0 0 0" />
		<parent link="frame_Link" />
		<child link="right_down_fin_Link" />
		<axis xyz="0 -1 0" />
		<limit lower="-1.57" upper="1.57" effort="0" velocity="0" />
	</joint>
	<!-- 机械臂部分 -->
	<joint name="arm1_bearing_joint" type="revolute">
		<origin xyz="0.159 0.017 0.229" rpy="0 0 0" />
		<parent link="frame_Link" />
		<child link="arm1_Link" />
		<axis xyz="0 0 1" />
		<limit lower="-2.0" upper="2.0" effort="0" velocity="0" />
	</joint>
	<link name="arm1_Link">
		<inertial>
			<origin xyz="0 3.4694E-18 0.024881" rpy="0 0 0" />
			<mass value="0.072961" />
			<inertia ixx="2.5689E-05" ixy="3.1598E-22" ixz="2.3664E-21" iyy="2.6532E-05" iyz="1.1228E-21" izz="2.064E-05" />
		</inertial>
		<visual>
			<origin xyz="0 0 0" rpy="0 0 0" />
			<geometry>
				<mesh filename="package://rescue_new/meshes/arm1_Link.STL" />
			</geometry>
			<material name="">
				<color rgba="1 0.4 0.37 1" />
			</material>
		</visual>
		<collision>
			<origin xyz="0 0 0" rpy="0 0 0" />
			<geometry>
				<mesh filename="package://rescue_new/meshes/arm1_Link.STL" />
			</geometry>
		</collision>
	</link>
	<joint name="arm2_arm1_joint" type="revolute">
		<origin xyz="0 0 0.037" rpy="0 0 0" />
		<parent link="arm1_Link" />
		<child link="arm2_Link" />
		<axis xyz="0 1 0" />
		<limit lower="-1.55" upper="1.4935" effort="0" velocity="0" />
	</joint>
	<link name="arm2_Link">
		<inertial>
			<origin xyz="-0.01735 0.0047967 0.17002" rpy="0 0 0" />
			<mass value="0.35607" />
			<inertia ixx="0.0070072" ixy="-0.00026676" ixz="0.00046445" iyy="0.0063258" iyz="-0.00079961" izz="0.0011004" />
		</inertial>
		<visual>
			<origin xyz="0 0 0" rpy="0 0 0" />
			<geometry>
				<mesh filename="package://rescue_new/meshes/arm2_Link.STL" />
			</geometry>
			<material name="">
				<color rgba="1 0.98 0.62 1" />
			</material>
		</visual>
		<collision>
			<origin xyz="0 0 0" rpy="0 0 0" />
			<geometry>
				<mesh filename="package://rescue_new/meshes/arm2_Link.STL" />
			</geometry>
		</collision>
	</link>
    <joint name="arm3_arm2_joint" type="revolute">
		<origin xyz="0 0.05715 0.36" rpy="1.8121E-15 0.034441 2.8069E-15" />
		<parent link="arm2_Link" />
		<child link="arm3_Link" />
		<axis xyz="0 1 0" />
		<limit lower="-2.6" upper="2" effort="0" velocity="0" />
	</joint>
	<link name="arm3_Link">
		<inertial>
			<origin xyz="0.20711 -0.00070341 0.0017452" rpy="0 0 0" />
			<mass value="0.10124" />
			<inertia ixx="2.3141E-05" ixy="1.4649E-05" ixz="1.5792E-06" iyy="0.0013066" iyz="1.244E-07" izz="0.0012991" />
		</inertial>
		<visual>
			<origin xyz="0 0 0" rpy="0 0 0" />
			<geometry>
				<mesh filename="package://rescue_new/meshes/arm3_Link.STL" />
			</geometry>
			<material name="">
				<color rgba="0.27 0.8 1 1" />
			</material>
		</visual>
		<collision>
			<origin xyz="0 0 0" rpy="0 0 0" />
			<geometry>
				<mesh filename="package://rescue_new/meshes/arm3_Link.STL" />
			</geometry>
		</collision>
	</link>
	<joint name="pt1_arm_joint" type="revolute">
		<origin xyz="0.314 0 -0.003" rpy="-2.2342E-15 3.6082E-16 -2.4361E-16" />
		<parent link="arm3_Link" />
		<child link="pt1_Link" />
		<axis xyz="0 0 1" />
		<limit lower="-1.56302" upper="1.0501" effort="0" velocity="0" />
	</joint>
	<link name="pt1_Link">
		<inertial>
			<origin xyz="0.044077 0.029007 0.0089778" rpy="0 0 0" />
			<mass value="0.075063" />
			<inertia ixx="4.1082E-05" ixy="1.4895E-05" ixz="1.4511E-05" iyy="5.8057E-05" iyz="3.8483E-06" izz="6.3298E-05" />
		</inertial>
		<visual>
			<origin xyz="0 0 0" rpy="0 0 0" />
			<geometry>
				<mesh filename="package://rescue_new/meshes/pt1_Link.STL" />
			</geometry>
			<material name="">
				<color rgba="0.55 0.21 1 1" />
			</material>
		</visual>
		<collision>
			<origin xyz="0 0 0" rpy="0 0 0" />
			<geometry>
				<mesh filename="package://rescue_new/meshes/pt1_Link.STL" />
			</geometry>
		</collision>
	</link>
	<joint name="pt2_pt1_joint" type="revolute">
		<origin xyz="0.0735 -0.0055 0.017" rpy="-2.0532E-15 -2.4702E-15 -1.7413E-15" />
		<parent link="pt1_Link" />
		<child link="pt2_Link" />
		<axis xyz="0 1 0" />
		<limit lower="-1.0444" upper="0.802661" effort="0" velocity="0" />
	</joint>
	<link name="pt2_Link">
		<inertial>
			<origin xyz="-0.00295 0.0014665 0.0054287" rpy="0 0 0" />
			<mass value="0.058403" />
			<inertia ixx="2.8371E-05" ixy="4.0133E-07" ixz="-4.584E-06" iyy="3.0457E-05" iyz="-5.714E-07" izz="1.2557E-05" />
		</inertial>
		<visual>
			<origin xyz="0 0 0" rpy="0 0 0" />
			<geometry>
				<mesh filename="package://rescue_new/meshes/pt2_Link.STL" />
			</geometry>
			<material name="">
				<color rgba="0.78 0.1 0 1" />
			</material>
		</visual>
		<collision>
			<origin xyz="0 0 0" rpy="0 0 0" />
			<geometry>
				<mesh filename="package://rescue_new/meshes/pt2_Link.STL" />
			</geometry>
		</collision>
	</link>
	<joint name="rotate_joint" type="revolute">
		<origin xyz="0.0215 0 -0.0145" rpy="2.2731E-15 7.6328E-17 -2.0733E-16" />
		<parent link="pt2_Link" />
		<child link="paw_rotation_Link" />
		<axis xyz="1 0 0" />
		<limit lower="-1" upper="3.14" effort="0" velocity="0" />
	</joint>
	<link name="paw_rotation_Link">
		<inertial>
			<origin xyz="0.045466 -2.7756E-17 -1.1102E-16" rpy="0 0 0" />
			<mass value="0.22083" />
			<inertia ixx="0.00017979" ixy="1.124E-20" ixz="8.0468E-21" iyy="0.00027562" iyz="-1.3329E-11" izz="0.00032364" />
		</inertial>
		<visual>
			<origin xyz="0 0 0" rpy="1.57 0 0" />
			<geometry>
				<mesh filename="package://rescue_new/meshes/paw_rotation_Link.STL" />
			</geometry>
			<material name="">
				<color rgba="0.2 0.2 0.2 1" />
			</material>
		</visual>
		<collision>
			<origin xyz="0 0 0" rpy="0 0 0" />
			<geometry>
				<mesh filename="package://rescue_new/meshes/paw_rotation_Link.STL" />
			</geometry>
		</collision>
	</link>
    <!-- 虚构一个爪子的位置 -->
    <!--joint name="paw" type="revolute">
        <origin xyz="0 0 0" rpy=" 0 0 0" />
		<parent link="paw_rotation_Link" />
		<child link="paw_Link" />
		<axis xyz="1 0 0" />
		<limit lower="0" upper="0.785" effort="0" velocity="0" />
    </joint>
    <link name="paw_Link">
        <visual>  
      <geometry>  
        <box size="0 0 1"/>  
      </geometry>  
      <material name="white"/>  
    </visual>  
    </link-->
	<!-- 轮子部分 -->
	<link name="left_up_wheel_Link">
		<inertial>
			<origin xyz="-2.77555756156289E-17 -6.93889390390723E-18 0.025" rpy="0 0 0" />
			<mass value="1.24155741669869" />
			<inertia ixx="0.00283364787737864" ixy="-2.97972422202132E-36" ixz="-1.41172157875716E-21" iyy="0.00283364787737864" iyz="2.06446195363164E-35" izz="0.00514998016446615" />
		</inertial>
		<visual>
			<origin xyz="0 0 0" rpy="0 0 0" />
			<geometry>
				<mesh filename="package://rescue_new/meshes/left_up_wheel_Link.STL" />
			</geometry>
			<material name="Black" />
		</visual>
		<collision>
			<origin xyz="0 0 0" rpy="0 0 0" />
			<geometry>
				<mesh filename="package://rescue_new/meshes/left_up_wheel_Link.STL" />
			</geometry>
		</collision>
	</link>
	<joint name="left_up_wheel_base_joint" type="continuous">
		<origin xyz="0.2 0.114 -0.05325" rpy="1.5707963267949 0 3.14159265358979" />
		<parent link="frame_Link" />
		<child link="left_up_wheel_Link" />
		<axis xyz="0 0 1" />
	</joint>
	<link name="left_down_wheel_Link">
		<inertial>
			<origin xyz="2.77555756156289E-17 -6.93889390390723E-18 0.025" rpy="0 0 0" />
			<mass value="1.24155741669869" />
			<inertia ixx="0.00283364787737864" ixy="-2.97972422202132E-36" ixz="-1.41172157875716E-21" iyy="0.00283364787737864" iyz="2.18201138871387E-35" izz="0.00514998016446615" />
		</inertial>
		<visual>
			<origin xyz="0 0 0" rpy="0 0 0" />
			<geometry>
				<mesh filename="package://rescue_new/meshes/left_down_wheel_Link.STL" />
			</geometry>
			<material name="Black" />
		</visual>
		<collision>
			<origin xyz="0 0 0" rpy="0 0 0" />
			<geometry>
				<mesh filename="package://rescue_new/meshes/left_down_wheel_Link.STL" />
			</geometry>
		</collision>
	</link>
	<joint name="left_down_wheel_base_joint" type="continuous">
		<origin xyz="-0.2 0.114 -0.05325" rpy="1.5707963267949 0 3.14159265358979" />
		<parent link="frame_Link" />
		<child link="left_down_wheel_Link" />
		<axis xyz="0 0 1" />
	</joint>
	<link name="right_up_wheel_Link">
		<inertial>
			<origin xyz="0 0 -0.025" rpy="0 0 0" />
			<mass value="1.24155741669869" />
			<inertia ixx="0.00283364787737864" ixy="-2.97972422202131E-36" ixz="4.12373035143234E-36" iyy="0.00283364787737864" iyz="3.01220427398211E-36" izz="0.00514998016446615" />
		</inertial>
		<visual>
			<origin xyz="0 0 0" rpy="0 0 0" />
			<geometry>
				<mesh filename="package://rescue_new/meshes/right_up_wheel_Link.STL" />
			</geometry>
			<material name="Black" />
		</visual>
		<collision>
			<origin xyz="0 0 0" rpy="0 0 0" />
			<geometry>
				<mesh filename="package://rescue_new/meshes/right_up_wheel_Link.STL" />
			</geometry>
		</collision>
	</link>
	<joint name="right_up_wheel_base_joint" type="continuous">
		<origin xyz="0.2 -0.114 -0.05325" rpy="1.5707963267949 0 3.14159265358979" />
		<parent link="frame_Link" />
		<child link="right_up_wheel_Link" />
		<axis xyz="0 0 1" />
	</joint>
	<link name="right_down_wheel_Link">
		<inertial>
			<origin xyz="0 0 -0.025" rpy="0 0 0" />
			<mass value="1.24155741669869" />
			<inertia ixx="0.00283364787737864" ixy="-2.97972422202132E-36" ixz="4.19264129766795E-36" iyy="0.00283364787737864" iyz="2.93873587705573E-36" izz="0.00514998016446615" />
		</inertial>
		<visual>
			<origin xyz="0 0 0" rpy="0 0 0" />
			<geometry>
				<mesh filename="package://rescue_new/meshes/right_down_wheel_Link.STL" />
			</geometry>
			<material name="Black" />
		</visual>
		<collision>
			<origin xyz="0 0 0" rpy="0 0 0" />
			<geometry>
				<mesh filename="package://rescue_new/meshes/right_down_wheel_Link.STL" />
			</geometry>
		</collision>
	</link>
	<joint name="right_down_wheel_base_joint" type="continuous">
		<origin xyz="-0.2 -0.114 -0.05325" rpy="1.5707963267949 0 3.14159265358979" />
		<parent link="frame_Link" />
		<child link="right_down_wheel_Link" />
		<axis xyz="0 0 1" />
	</joint>
</robot>
